Exception caught!

--- Traceback using traceback.print_exc() ---
Traceback (most recent call last):
  File "/home/tourist/diy/Full-stack-Python/07-exceptions/traceback_module.py", line 9, in <module>
    buggy_function()
  File "/home/tourist/diy/Full-stack-Python/07-exceptions/traceback_module.py", line 4, in buggy_function
    return 1 / 0  # This will raise a ZeroDivisionError
ZeroDivisionError: division by zero

--- Traceback as string ---
Traceback (most recent call last):
  File "/home/tourist/diy/Full-stack-Python/07-exceptions/traceback_module.py", line 9, in <module>
    buggy_function()
  File "/home/tourist/diy/Full-stack-Python/07-exceptions/traceback_module.py", line 4, in buggy_function
    return 1 / 0  # This will raise a ZeroDivisionError
ZeroDivisionError: division by zero

--- Stack trace details ---
File "/home/tourist/diy/Full-stack-Python/07-exceptions/traceback_module.py", line 25, in <module>
    for line in traceback.format_stack():
